Workbook

Sheet Resumo Executivo
A1: Resumo - Migração OCI → AWS
A2: KPIs consolidados para decisão da diretoria
A4: Custo Mensal OCI (Atual) | B4: ='Comparativo Mensal'!C53 -> 52600
A5: Custo Mensal AWS (Novo) | B5: ='Comparativo Mensal'!D53 -> 7805
A6: Economia Mensal | B6: ='Comparativo Mensal'!E53 -> 44795
A7: Redução Percentual | B7: ='Comparativo Mensal'!F53 -> 0.85161597
A8: Economia Anual | B8: ='Comparativo Mensal'!E53*12 -> 537540
A9: Investimento na Migração | B9: ='Custos de Migração'!E17 -> 70725
A10: Payback | B10: =IF('Comparativo Mensal'!E53=0,"N/A",CEILING('Custos de Migração'!E17/'Comparativo Mensal'!E53,1)) -> 2
A11: ROI 1º Ano | B11: =IF('Custos de Migração'!E17=0,0,('Comparativo Mensal'!E53*12-'Custos de Migração'!E17)/'Custos de Migração'!E17) -> 6.6004242
A12: Quick Wins (mensal) | B12: =#REF! -> #REF!
A14: Principais Drivers da Economia
A15: 1. Eliminação total de licenciamento Windows Server (VMs app + workers)
A16: 2. Eliminação dos workers de sincronização Oracle↔MySQL
A17: 3. Substituição Oracle Database por Aurora MySQL (custo ~55% menor)
A18: 4. RabbitMQ open-source substitui serviço de mensageria gerenciado
A19: 5. Kubernetes (EKS) consolida workloads com auto-scaling e self-healing
A20: 6. Redução drástica de overhead operacional (patching, suporte, monitoring)

Sheet Comparativo Mensal
B1: Migração OCI → AWS — Comparativo de Custos Mensal
B4: Recurso / Serviço | C4: OCI (Atual) | D4: AWS (Novo) | E4: Economia (R$) | F4: Redução (%) | G4: Observações
B5: Compute & Runtime
B6: VMs Windows c/ IIS (apps .NET) | C6: 30000 | D6: 0 | E6: =C6-D6 -> 30000 | F6: =IF(C6=0,0,(C6-D6)/C6) -> 1 | G6: Migram para EKS (eliminadas)
B7: Licenciamento Windows Server (VMs app) | C7: 4200 | D7: 0 | E7: =C7-D7 -> 4200 | F7: =IF(C7=0,0,(C7-D7)/C7) -> 1 | G7: Containers Linux = sem licença Windows
B8: EKS (Kubernetes gerenciado) | C8: 0 | D8: 900 | E8: =C8-D8 -> -900 | F8: =IF(C8=0,0,(C8-D8)/C8) -> 0 | G8: Cluster EKS Autopilot / managed node groups
B9: EC2 Spot / Reserved (nodes EKS) | C9: 0 | D9: 430 | E9: =C9-D9 -> -430 | F9: =IF(C9=0,0,(C9-D9)/C9) -> 0 | G9: Nodes Linux otimizados (Graviton ARM)
B10: Subtotal Compute & Runtime | C10: =SUM(C6:C9) -> 34200 | D10: =SUM(D6:D9) -> 1330 | E10: =SUM(E6:E9) -> 32870 | F10: =IF(C10=0,0,(C10-D10)/C10) -> 0.96111111
B11: Banco de Dados
B12: Oracle Database (OCI) | C12: 0 | D12: 0 | E12: =C12-D12 -> 0 | F12: =IF(C12=0,0,(C12-D12)/C12) -> 0 | G12: Migração para MySQL/Aurora na AWS
B13: MySQL (OCI — destino sync) | C13: 1200 | D13: 0 | E13: =C13-D13 -> 1200 | F13: =IF(C13=0,0,(C13-D13)/C13) -> 1 | G13: Consolidado na AWS
B14: Amazon Aurora MySQL | C14: 0 | D14: 1800 | E14: =C14-D14 -> -1800 | F14: =IF(C14=0,0,(C14-D14)/C14) -> 0 | G14: Substitui Oracle + MySQL OCI
B15: Amazon ElastiCache (Redis) | C15: 0 | D15: 650 | E15: =C15-D15 -> -650 | F15: =IF(C15=0,0,(C15-D15)/C15) -> 0 | G15: Cache de sessão e aplicação
B16: Subtotal Banco de Dados | C16: =SUM(C12:C15) -> 1200 | D16: =SUM(D12:D15) -> 2450 | E16: =SUM(E12:E15) -> -1250 | F16: =IF(C16=0,0,(C16-D16)/C16) -> -1.0416667
B17: Mensageria & Filas
B18: SQS/SNS | C18: 3000 | D18: 0 | E18: =C18-D18 -> 3000 | F18: =IF(C18=0,0,(C18-D18)/C18) -> 1 | G18: Substituído por RabbitMQ no EKS
B19: RabbitMQ (self-hosted no EKS) | C19: 0 | D19: 0 | E19: =C19-D19 -> 0 | F19: =IF(C19=0,0,(C19-D19)/C19) -> 0 | G19: Open-source, roda como pod no cluster
B20: Recursos do pod RabbitMQ (CPU/RAM) | C20: 0 | D20: 1600 | E20: =C20-D20 -> -1600 | F20: =IF(C20=0,0,(C20-D20)/C20) -> 0 | G20: Incluso nos nodes, custo marginal
B21: Subtotal Mensageria & Filas | C21: =SUM(C18:C20) -> 3000 | D21: =SUM(D18:D20) -> 1600 | E21: =SUM(E18:E20) -> 1400 | F21: =IF(C21=0,0,(C21-D21)/C21) -> 0.46666667
B22: Storage & CDN
B23: OCI Object Storage | C23: 0 | D23: 0 | E23: =C23-D23 -> 0 | F23: =IF(C23=0,0,(C23-D23)/C23) -> 0
B24: Amazon S3 | C24: 0 | D24: 280 | E24: =C24-D24 -> -280 | F24: =IF(C24=0,0,(C24-D24)/C24) -> 0 | G24: Migração de buckets
B25: CloudFront (CDN) | C25: 0 | D25: 200 | E25: =C25-D25 -> -200 | F25: =IF(C25=0,0,(C25-D25)/C25) -> 0 | G25: CDN para assets estáticos
B26: OCI Load Balancer | C26: 1200 | D26: 0 | E26: =C26-D26 -> 1200 | F26: =IF(C26=0,0,(C26-D26)/C26) -> 1
B27: AWS ALB (Application Load Balancer) | C27: 0 | D27: 0 | E27: =C27-D27 -> 0 | F27: =IF(C27=0,0,(C27-D27)/C27) -> 0 | G27: Integrado com EKS Ingress (Já implementado)
B28: Subtotal Storage & CDN | C28: =SUM(C23:C27) -> 1200 | D28: =SUM(D23:D27) -> 480 | E28: =SUM(E23:E27) -> 720 | F28: =IF(C28=0,0,(C28-D28)/C28) -> 0.6
B29: Rede & Segurança
B30: Egress / Tráfego de rede (OCI) | C30: 600 | D30: 0 | E30: =C30-D30 -> 600 | F30: =IF(C30=0,0,(C30-D30)/C30) -> 1
B31: Egress / Tráfego de rede (AWS) | C31: 0 | D31: 600 | E31: =C31-D31 -> -600 | F31: =IF(C31=0,0,(C31-D31)/C31) -> 0 | G31: AWS egress tipicamente mais caro
B32: VPN / Interconexão OCI | C32: 0 | D32: 1000 | E32: =C32-D32 -> -1000 | F32: =IF(C32=0,0,(C32-D32)/C32) -> 0
B33: AWS VPC / NAT Gateway | C33: 0 | D33: 0 | E33: =C33-D33 -> 0 | F33: =IF(C33=0,0,(C33-D33)/C33) -> 0
B34: DNS (Route 53) | C34: 0 | D34: 0 | E34: =C34-D34 -> 0 | F34: =IF(C34=0,0,(C34-D34)/C34) -> 0
B35: WAF (AWS WAF) | C35: 0 | D35: 0 | E35: =C35-D35 -> 0 | F35: =IF(C35=0,0,(C35-D35)/C35) -> 0 | G35: Proteção de API
B36: ACM (Certificados SSL) | C36: 0 | D36: 0 | E36: =C36-D36 -> 0 | F36: =IF(C36=0,0,(C36-D36)/C36) -> 0 | G36: Gratuito na AWS
B37: Subtotal Rede & Segurança | C37: =SUM(C30:C36) -> 600 | D37: =SUM(D30:D36) -> 1600 | E37: =SUM(E30:E36) -> -1000 | F37: =IF(C37=0,0,(C37-D37)/C37) -> -1.6666667
B38: DevOps & Observabilidade
B39: CI/CD Jenkins | C39: 4350 | D39: 0 | E39: =C39-D39 -> 4350 | F39: =IF(C39=0,0,(C39-D39)/C39) -> 1
B40: Bitbucket Pipelines (CI/CD) | C40: 0 | D40: 0 | E40: =C40-D40 -> 0 | F40: =IF(C40=0,0,(C40-D40)/C40) -> 0 | G40: Reuso de pipelines existentes
B41: Monitoring OCI | C41: 350 | D41: 0 | E41: =C41-D41 -> 350 | F41: =IF(C41=0,0,(C41-D41)/C41) -> 1
B42: Amazon CloudWatch + Grafana | C42: 0 | D42: 280 | E42: =C42-D42 -> -280 | F42: =IF(C42=0,0,(C42-D42)/C42) -> 0 | G42: Logs, métricas, alertas
...

Sheet Quick Wins
A1: Quick Wins — Ganhos Imediatos com a Migração OCI → AWS
A2: Impactos diretos que geram economia desde o primeiro mês pós-migração
A4: Quick Win | B4: Justificativa / Impacto
A5: Eliminação de VMs Windows (IIS) | B5: Apps .NET migram para containers Linux no EKS. Zero custo de VM, zero licenciamento Windows Server.
A6: Eliminação de licenças Windows Server | B6: VMs de app + workers usavam Windows Server. Containers Linux eliminam 100% desse custo.
A7: Eliminação dos Workers de Sincronização | B7: Dados consolidados na AWS (Aurora). Sem necessidade de sync Oracle↔MySQL, workers desligados.
A8: Redução de Oracle Database → Aurora MySQL | B8: Oracle DB na OCI para diminuição do monolito que temos hoje
A9: RabbitMQ (open-source) no lugar de SQS/SNS | B9: RabbitMQ roda como pod no EKS (custo marginal de ~R$ 180). Substitui serviço gerenciado (R$ 450).
A10: Eliminação de manutenção Windows | B10: Sem patching de OS Windows, sem atualizações de IIS, sem reinicializações programadas.
A11: Redução de horas de suporte operacional | B11: K8s gerenciado + containers = menos tickets de infra, deploys self-healing.
A12: Eliminação de antivírus/EDR em VMs | B12: Containers Linux efêmeros não requerem agentes de segurança de endpoint.
A13: Eliminação de monitoramento de workers | B13: Workers eliminados = dashboards, alertas e runbooks de sync descontinuados.

Sheet Custos de Migração
B1: Custos de Migração OCI → AWS (One-Time)
B2: Investimento único para execução da migração
B4: Fase / Item | C4: Custo (R$) | D4: Horas | E4: Custo Total | F4: Detalhamento
B5: Discovery & Assessment | C5: 6000 | D5: 48 | E5: =C5 -> 6000 | F5: Levantamento de workloads OCI, dependências, sizing AWS
B6: Containerização das apps .NET (IIS → Docker) | C6: 15000 | D6: 120 | E6: =C6 -> 15000 | F6: Dockerfile, health checks, remoção deps IIS, testes
B7: Setup EKS + Networking (VPC, ALB, NAT) | C7: 8000 | D7: 64 | E7: =C7 -> 8000 | F7: Cluster EKS, node groups, Helm charts, Ingress
B8: Migração Oracle → Aurora MySQL | C8: 12000 | D8: 96 | E8: =C8 -> 12000 | F8: Schema conversion (SCT), DMS, validação de dados
B9: Setup RabbitMQ no EKS | C9: 3000 | D9: 24 | E9: =C9 -> 3000 | F9: Helm chart, exchanges, filas, políticas de HA
B10: Migração de Storage (OCI → S3) | C10: 2000 | D10: 16 | E10: =C10 -> 2000 | F10: Buckets, permissões IAM, lifecycle policies
B11: Reconfiguração CI/CD (GitHub Actions) | C11: 4000 | D11: 32 | E11: =C11 -> 4000 | F11: Pipelines, ECR push, deploy EKS, secrets
B12: DNS, SSL e cutover de tráfego | C12: 1500 | D12: 12 | E12: =C12 -> 1500 | F12: Route 53, ACM, blue-green ou canary deploy
B13: Descomissionamento dos Workers de sync | C13: 2000 | D13: 16 | E13: =C13 -> 2000 | F13: Validação de dados, shutdown, cleanup OCI
B14: Testes de carga e validação | C14: 5000 | D14: 40 | E14: =C14 -> 5000 | F14: Smoke tests, stress test, rollback plan
B15: Treinamento da equipe (AWS/EKS) | C15: 3000 | D15: 24 | E15: =C15 -> 3000 | F15: Workshops K8s, kubectl, CloudWatch, runbooks
B16: Contingência (15%) | C16: 0 | D16: 0 | E16: =SUM(E5:E15)*0.15 -> 9225 | F16: Buffer para imprevistos da migração
B17: TOTAL MIGRAÇÃO | D17: =SUM(D5:D16) -> 492 | E17: =SUM(E5:E16) -> 70725
B19: 📊 Payback da Migração
B20: Economia Mensal | C20: ='Comparativo Mensal'!E53 -> 44795
B21: Payback | C21: =IF(C20=0,"N/A",CEILING(E17/C20,1)) -> 2
B22: ROI 1º Ano | C22: =IF(E17=0,0,(C20*12-E17)/E17) -> 6.6004242
